<?xml version="1.0" encoding="UTF-8"?>
<!-- Generated by org.testng.reporters.JUnitXMLReporter -->
<testsuite hostname="XEB9JTKJUVWFXLY" ignored="0" name="这些是测试模块" tests="4" failures="2" timestamp="28 十月 2020 08:23:37 GMT" time="0.128" errors="0">
  <testcase name="test1" time="0.04" classname="com.tester.extend.demo.TestMethodsDemo"/>
  <testcase name="test2" time="0.002" classname="com.tester.extend.demo.TestMethodsDemo">
    <failure type="java.lang.AssertionError" message="expected [2] but found [1]">
      <![CDATA[java.lang.AssertionError: expected [2] but found [1]
	at com.tester.extend.demo.TestMethodsDemo.test2(TestMethodsDemo.java:15)
... Removed 30 stack frames]]>
    </failure>
  </testcase> <!-- test2 -->
  <testcase name="test3" time="0.001" classname="com.tester.extend.demo.TestMethodsDemo"/>
  <testcase name="logDemo" time="0.0" classname="com.tester.extend.demo.TestMethodsDemo">
    <failure type="java.lang.RuntimeException" message="这是我自己的运行时异常">
      <![CDATA[java.lang.RuntimeException: 这是我自己的运行时异常
	at com.tester.extend.demo.TestMethodsDemo.logDemo(TestMethodsDemo.java:24)
... Removed 24 stack frames]]>
    </failure>
  </testcase> <!-- logDemo -->
</testsuite> <!-- 这些是测试模块 -->
